Workbook

Sheet Fasted
B1: Glucose infusion | D1: Lactate infusion | F1: Glutamine infusion | H1: Alanine Infusion | J1: 3HB infusion | L1: Palmitic acid infusion | N1: Oleic acid infusion | P1: Linoleic acid infusion | R1: Seine infusion | T1: Glycine infusion | V1: Citrate infusion | X1: Acetate infusion | Z1: Glycerol infusion | AB1: BCAAs infusion | AD1: 6AAs infusion
B2: Mean | C2: SEM | D2: Mean | E2: SEM | F2: Mean | G2: SEM | H2: Mean | I2: SEM | J2: Mean | K2: SEM | L2: Mean | M2: SEM | N2: Mean | O2: SEM | P2: Mean | Q2: SEM | R2: Mean | S2: SEM | T2: Mean | U2: SEM | V2: Mean | W2: SEM | X2: Mean | Y2: SEM | Z2: Mean | AA2: SEM | AB2: Mean | AC2: SEM | AD2: Mean | AE2: SEM
A3: Serum
A4: glucose | B4: =Glucose!B19 -> 1 | C4: =Glucose!C19 -> 0.022032872 | D4: =Lactate!B19 -> 0.28711972 | E4: =Lactate!C19 -> 0.038587616 | F4: =Glutamine!B19 -> 0.064880126 | G4: =Glutamine!C19 -> 0.0077764139 | H4: =Alanine!B19 -> 0.19798248 | I4: =Alanine!C19 -> 0.024143091 | J4: ='3HB'!B19 -> 0.027422258 | K4: ='3HB'!C19 -> 0.0054043153 | L4: =Palmitate!B19 -> 0.034488789 | M4: =Palmitate!C19 -> 0.007964221 | N4: =Oleate!B19 -> 0.047279587 | O4: =Oleate!C19 -> 0.011719735 | P4: =Linoleate!B19 -> 0.083047278 | Q4: =Linoleate!C19 -> 0.017499026 | R4: =Serine!B19 -> 0.015827762 | S4: =Serine!C19 -> 0.0018707166 | T4: =Glycine!B19 -> 0.0057040408 | U4: =Glycine!C19 -> 0.00016452793 | V4: =Citrate!B19 -> 0.032813108 | W4: =Citrate!C19 -> 0.0053539999 | X4: =Acetate!B19 -> 0.015804596 | Y4: =Acetate!C19 -> 0.0020742474 | Z4: =Glycerol!B19 -> 0.34882157 | AA4: =Glycerol!C19 -> 0.057591848 | AB4: =BCAAs!B19 -> 0.0068492865 | AC4: =BCAAs!C19 -> 0.0014397144 | AD4: ='6AAs'!B19 -> 0.0099326995 | AE4: ='6AAs'!C19 -> 0.00081778094
A5: lactate | B5: =Glucose!B20 -> 0.64790843 | C5: =Glucose!C20 -> 0.01778097 | D5: =Lactate!B20 -> 1 | E5: =Lactate!C20 -> 5.0907085e-17 | F5: =Glutamine!B20 -> 0.055569964 | G5: =Glutamine!C20 -> 0.0054639647 | H5: =Alanine!B20 -> 0.21608123 | I5: =Alanine!C20 -> 0.016244571 | J5: ='3HB'!B20 -> 0.02449984 | K5: ='3HB'!C20 -> 0.005717215 | L5: =Palmitate!B20 -> 0.028673069 | M5: =Palmitate!C20 -> 0.0046820575 | N5: =Oleate!B20 -> 0.093401089 | O5: =Oleate!C20 -> 0.027573955 | P5: =Linoleate!B20 -> 0.094258412 | Q5: =Linoleate!C20 -> 0.01645309 | R5: =Serine!B20 -> 0.030673073 | S5: =Serine!C20 -> 0.025491652 | T5: =Glycine!B20 -> 0.0080060356 | U5: =Glycine!C20 -> 0.0012109 | V5: =Citrate!B20 -> 0.023710617 | W5: =Citrate!C20 -> 0.0011057456 | X5: =Acetate!B20 -> 0.016317966 | Y5: =Acetate!C20 -> 0.0027282919 | Z5: =Glycerol!B20 -> 0.24734321 | AA5: =Glycerol!C20 -> 0.031306849 | AB5: =BCAAs!B20 -> 0.011731305 | AC5: =BCAAs!C20 -> 0.00035329345 | AD5: ='6AAs'!B20 -> 0.016036684 | AE5: ='6AAs'!C20 -> 0.0040692361
A6: glutamine | B6: =Glucose!B21 -> 0.12237446 | C6: =Glucose!C21 -> 0.010740745 | D6: =Lactate!B21 -> 0.24343369 | E6: =Lactate!C21 -> 0.01598167 | F6: =Glutamine!B21 -> 1 | G6: =Glutamine!C21 -> 0 | H6: =Alanine!B21 -> 0.077417374 | I6: =Alanine!C21 -> 0.011516131 | J6: ='3HB'!B21 -> 0.03966253 | K6: ='3HB'!C21 -> 0.0058679483 | L6: =Palmitate!B21 -> 0.062158673 | M6: =Palmitate!C21 -> 0.0072655166 | N6: =Oleate!B21 -> 0.095851214 | O6: =Oleate!C21 -> 0.010611912 | P6: =Linoleate!B21 -> 0.14034473 | Q6: =Linoleate!C21 -> 0.011950888 | R6: =Serine!B21 -> 0.00011697398 | S6: =Serine!C21 -> 0.00011697398 | T6: =Glycine!B21 -> 0.0040809892 | U6: =Glycine!C21 -> 1.1344626e-05 | V6: =Citrate!B21 -> 0.023720333 | W6: =Citrate!C21 -> 0.0017429741 | X6: =Acetate!B21 -> 0.025758265 | Y6: =Acetate!C21 -> 0.0082269821 | Z6: =Glycerol!B21 -> 0.037771838 | AA6: =Glycerol!C21 -> 0.0038787286 | AB6: =BCAAs!B21 -> 0.014597735 | AC6: =BCAAs!C21 -> 0.0021598771 | AD6: ='6AAs'!B21 -> 0.015198042 | AE6: ='6AAs'!C21 -> 0.0020949723
A7: alanine | B7: =Glucose!B22 -> 0.44702171 | C7: =Glucose!C22 -> 0.014909845 | D7: =Lactate!B22 -> 0.57315638 | E7: =Lactate!C22 -> 0.077682825 | F7: =Glutamine!B22 -> 0.0372689 | G7: =Glutamine!C22 -> 0.0045030805 | H7: =Alanine!B22 -> 1 | I7: =Alanine!C22 -> 0 | J7: ='3HB'!B22 -> 0.00079163286 | K7: ='3HB'!C22 -> 0.00051638827 | L7: =Palmitate!B22 -> 0.01130208 | M7: =Palmitate!C22 -> 0.0046681154 | N7: =Oleate!B22 -> 0.046499528 | O7: =Oleate!C22 -> 0.010885414 | P7: =Linoleate!B22 -> 0.03938487 | Q7: =Linoleate!C22 -> 0.011447347 | R7: =Serine!B22 -> 0.0023948943 | S7: =Serine!C22 -> 0.0012380723 | T7: =Glycine!B22 -> 0.021865987 | U7: =Glycine!C22 -> 0.00011436847 | V7: =Citrate!B22 -> 0.0080895392 | W7: =Citrate!C22 -> 0.0019070691 | X7: =Acetate!B22 -> 0.0018428355 | Y7: =Acetate!C22 -> 0.0010499617 | Z7: =Glycerol!B22 -> 0.13531249 | AA7: =Glycerol!C22 -> 0.045438698 | AB7: =BCAAs!B22 -> 0.014927405 | AC7: =BCAAs!C22 -> 0.0072778938 | AD7: ='6AAs'!B22 -> 0.022915996 | AE7: ='6AAs'!C22 -> 0.007311378
A8: 3-hydroxybutyrate | B8: =Glucose!B23 -> 0.0068719553 | C8: =Glucose!C23 -> 0.0020126255 | D8: =Lactate!B23 -> 0.010355966 | E8: =Lactate!C23 -> 0.003187904 | F8: =Glutamine!B23 -> 0.0018664053 | G8: =Glutamine!C23 -> 0.0003943307 | H8: =Alanine!B23 -> 0 | I8: =Alanine!C23 -> 0 | J8: ='3HB'!B23 -> 1 | K8: ='3HB'!C23 -> 0 | L8: =Palmitate!B23 -> 0.16948041 | M8: =Palmitate!C23 -> 0.028635725 | N8: =Oleate!B23 -> 0.226096 | O8: =Oleate!C23 -> 0.02308602 | P8: =Linoleate!B23 -> 0.31594964 | Q8: =Linoleate!C23 -> 0.031034239 | R8: =Serine!B23 -> 0.00023420639 | S8: =Serine!C23 -> 0.00023420639 | T8: =Glycine!B23 -> 0.0025638424 | U8: =Glycine!C23 -> 0.0025638424 | V8: =Citrate!B23 -> 0.0012008688 | W8: =Citrate!C23 -> 0.00059854091 | X8: =Acetate!B23 -> 0.0085043385 | Y8: =Acetate!C23 -> 0.0029980922 | Z8: =Glycerol!B23 -> 0.0025754906 | AA8: =Glycerol!C23 -> 0.0014890871 | AB8: =BCAAs!B23 -> 0.026390607 | AC8: =BCAAs!C23 -> 0.0040272721 | AD8: ='6AAs'!B23 -> 0.022700309 | AE8: ='6AAs'!C23 -> 0.0067919153
A9: palmitic acid | B9: =Glucose!B24 -> 7.5895518e-05 | C9: =Glucose!C24 -> 4.1567601e-05 | D9: =Lactate!B24 -> 0.0012146902 | E9: =Lactate!C24 -> 0.0012146902 | F9: =Glutamine!B24 -> 0 | G9: =Glutamine!C24 -> 0 | H9: =Alanine!B24 -> 2.0187744e-05 | I9: =Alanine!C24 -> 2.0187744e-05 | J9: ='3HB'!B24 -> 0 | K9: ='3HB'!C24 -> 0 | L9: =Palmitate!B24 -> 1 | M9: =Palmitate!C24 -> 0 | N9: =Oleate!B24 -> 0.00019584967 | O9: =Oleate!C24 -> 0.00015754895 | P9: =Linoleate!B24 -> 0.00040970928 | Q9: =Linoleate!C24 -> 0.00020421033 | R9: =Serine!B24 -> 0 | S9: =Serine!C24 -> 0 | T9: =Glycine!B24 -> 0 | U9: =Glycine!C24 -> 0 | V9: =Citrate!B24 -> 0.00014597769 | W9: =Citrate!C24 -> 0.00013866627 | X9: =Acetate!B24 -> 0.00027647744 | Y9: =Acetate!C24 -> 0.00012830359 | Z9: =Glycerol!B24 -> 0.00099057931 | AA9: =Glycerol!C24 -> 0.00085534292 | AB9: =BCAAs!B24 -> 0 | AC9: =BCAAs!C24 -> 0 | AD9: ='6AAs'!B24 -> 0.00015657143 | AE9: ='6AAs'!C24 -> 0.00015657143
A10: oleic acid | B10: =Glucose!B25 -> 0.00012408602 | C10: =Glucose!C25 -> 6.4894752e-05 | D10: =Lactate!B25 -> 0.00028767448 | E10: =Lactate!C25 -> 6.5915725e-05 | F10: =Glutamine!B25 -> 0.00024124687 | G10: =Glutamine!C25 -> 0.00017765492 | H10: =Alanine!B25 -> 6.1947115e-05 | I10: =Alanine!C25 -> 6.1947115e-05 | J10: ='3HB'!B25 -> 0 | K10: ='3HB'!C25 -> 0 | L10: =Palmitate!B25 -> 0.0026361854 | M10: =Palmitate!C25 -> 0.001897158 | N10: =Oleate!B25 -> 1 | O10: =Oleate!C25 -> 0 | P10: =Linoleate!B25 -> 0.0044265358 | Q10: =Linoleate!C25 -> 0.0016205426 | R10: =Serine!B25 -> 0.00034899002 | S10: =Serine!C25 -> 5.2686245e-05 | T10: =Glycine!B25 -> 0 | U10: =Glycine!C25 -> 0 | V10: =Citrate!B25 -> 2.7748772e-05 | W10: =Citrate!C25 -> 2.7748772e-05 | X10: =Acetate!B25 -> 6.7629948e-05 | Y10: =Acetate!C25 -> 5.1465682e-05 | Z10: =Glycerol!B25 -> 0.00053150219 | AA10: =Glycerol!C25 -> 0.00024186319 | AB10: =BCAAs!B25 -> 0.00017165971 | AC10: =BCAAs!C25 -> 0.00011649806 | AD10: ='6AAs'!B25 -> 0.00018569055 | AE10: ='6AAs'!C25 -> 0.00017626146
A11: linoleic acid | B11: =Glucose!B26 -> 0 | C11: =Glucose!C26 -> 0 | D11: =Lactate!B26 -> 0 | E11: =Lactate!C26 -> 0 | F11: =Glutamine!B26 -> 0 | G11: =Glutamine!C26 -> 0 | H11: =Alanine!B26 -> 0 | I11: =Alanine!C26 -> 0 | J11: ='3HB'!B26 -> 0 | K11: ='3HB'!C26 -> 0 | L11: =Palmitate!B26 -> 0.00016269626 | M11: =Palmitate!C26 -> 0.00016269626 | N11: =Oleate!B26 -> 0 | O11: =Oleate!C26 -> 0 | P11: =Linoleate!B26 -> 1 | Q11: =Linoleate!C26 -> 0 | R11: =Serine!B26 -> 3.17077e-05 | S11: =Serine!C26 -> 3.17077e-05 | T11: =Glycine!B26 -> 0.002722175 | U11: =Glycine!C26 -> 3.4373153e-05 | V11: =Citrate!B26 -> 0 | W11: =Citrate!C26 -> 0 | X11: =Acetate!B26 -> 0 | Y11: =Acetate!C26 -> 0 | Z11: =Glycerol!B26 -> 0.0024148067 | AA11: =Glycerol!C26 -> 0.002151884 | AB11: =BCAAs!B26 -> 0 | AC11: =BCAAs!C26 -> 0 | AD11: ='6AAs'!B26 -> 0 | AE11: ='6AAs'!C26 -> 0
A12: serine | B12: =Glucose!B27 -> 0.098022081 | C12: =Glucose!C27 -> 0.0090668806 | D12: =Lactate!B27 -> 0.052723546 | E12: =Lactate!C27 -> 0.0041674722 | F12: =Glutamine!B27 -> 0.0073851226 | G12: =Glutamine!C27 -> 0.00187272 | H12: =Alanine!B27 -> 0 | I12: =Alanine!C27 -> 0 | J12: ='3HB'!B27 -> 0.031040211 | K12: ='3HB'!C27 -> 0.029615916 | L12: =Palmitate!B27 -> 0 | M12: =Palmitate!C27 -> 0 | N12: =Oleate!B27 -> 0.0060299977 | O12: =Oleate!C27 -> 0.0060299977 | P12: =Linoleate!B27 -> 0.024729812 | Q12: =Linoleate!C27 -> 0.016188023 | R12: =Serine!B27 -> 1 | S12: =Serine!C27 -> 0 | T12: =Glycine!B27 -> 0.11363168 | U12: =Glycine!C27 -> 0.003725223 | V12: =Citrate!B27 -> 0.00033259446 | W12: =Citrate!C27 -> 0.00033259446 | X12: =Acetate!B27 -> 0.0021012244 | Y12: =Acetate!C27 -> 0.0021012244 | Z12: =Glycerol!B27 -> 0.040525322 | AA12: =Glycerol!C27 -> 0.010607779 | AB12: =BCAAs!B27 -> 0.0049252361 | AC12: =BCAAs!C27 -> 0.0030730301 | AD12: ='6AAs'!B27 -> 0 | AE12: ='6AAs'!C27 -> 0
A13: glycine | B13: =Glucose!B28 -> 0.039638625 | C13: =Glucose!C28 -> 0.012097856 | D13: =Lactate!B28 -> 0.01342871 | E13: =Lactate!C28 -> 0.0020141691 | F13: =Glutamine!B28 -> 0.0034859273 | G13: =Glutamine!C28 -> 0.0015068569 | H13: =Alanine!B28 -> 0 | I13: =Alanine!C28 -> 0 | J13: ='3HB'!B28 -> 0 | K13: ='3HB'!C28 -> 0 | L13: =Palmitate!B28 -> 0.0014696859 | M13: =Palmitate!C28 -> 0.0014696859 | N13: =Oleate!B28 -> 0.016735144 | O13: =Oleate!C28 -> 0.016735144 | P13: =Linoleate!B28 -> 0.006990757 | Q13: =Linoleate!C28 -> 0.0043549292 | R13: =Serine!B28 -> 0.24518449 | S13: =Serine!C28 -> 0.034218887 | T13: =Glycine!B28 -> 1 | U13: =Glycine!C28 -> 0 | V13: =Citrate!B28 -> 0.0021954748 | W13: =Citrate!C28 -> 0.0016737434 | X13: =Acetate!B28 -> 0.0014050881 | Y13: =Acetate!C28 -> 0.0014050881 | Z13: =Glycerol!B28 -> 0.012477296 | AA13: =Glycerol!C28 -> 0.0029889582 | AB13: =BCAAs!B28 -> 0.0048418159 | AC13: =BCAAs!C28 -> 0.0048418159 | AD13: ='6AAs'!B28 -> 0 | AE13: ='6AAs'!C28 -> 0
A14: citrate | B14: =Glucose!B29 -> 0.11567133 | C14: =Glucose!C29 -> 0.011397593 | D14: =Lactate!B29 -> 0.20216049 | E14: =Lactate!C29 -> 0.031065465 | F14: =Glutamine!B29 -> 0.089601782 | G14: =Glutamine!C29 -> 0.0015289856 | H14: =Alanine!B29 -> 0.025551412 | I14: =Alanine!C29 -> 0.0096279301 | J14: ='3HB'!B29 -> 0.052381991 | K14: ='3HB'!C29 -> 0.011072961 | L14: =Palmitate!B29 -> 0.046823482 | M14: =Palmitate!C29 -> 0.011529899 | N14: =Oleate!B29 -> 0.049100738 | O14: =Oleate!C29 -> 0.018403678 | P14: =Linoleate!B29 -> 0.035465934 | Q14: =Linoleate!C29 -> 0.035465934 | R14: =Serine!B29 -> 0.028140347 | S14: =Serine!C29 -> 0.0083709153 | T14: =Glycine!B29 -> 0.039447256 | U14: =Glycine!C29 -> 0.012161007 | V14: =Citrate!B29 -> 1 | W14: =Citrate!C29 -> 0 | X14: =Acetate!B29 -> 0.033140886 | Y14: =Acetate!C29 -> 0.010265237 | Z14: =Glycerol!B29 -> 0.014515216 | AA14: =Glycerol!C29 -> 0.0069690627 | AB14: =BCAAs!B29 -> 0.013186578 | AC14: =BCAAs!C29 -> 0.0025009137 | AD14: ='6AAs'!B29 -> 0.0026103466 | AE14: ='6AAs'!C29 -> 0.00067641546
A15: acetate | B15: =Glucose!B30 -> #REF! | C15: =Glucose!C30 -> #REF! | D15: =Lactate!B30 -> 0.11511102 | E15: =Lactate!C30 -> 0.014552898 | F15: =Glutamine!B30 -> 0.03582605 | G15: =Glutamine!C30 -> 0.0098035529 | H15: =Alanine!B30 -> NaN | I15: =Alanine!C30 -> NaN | J15: ='3HB'!B30 -> 0.069471312 | K15: ='3HB'!C30 -> 0.0083023139 | L15: =Palmitate!B30 -> 0.079309273 | M15: =Palmitate!C30 -> 0.0099164978 | N15: =Oleate!B30 -> 0.14010425 | O15: =Oleate!C30 -> 0.0092337711 | P15: =Linoleate!B30 -> NaN | Q15: =Linoleate!C30 -> NaN | R15: =Serine!B30 -> NaN | S15: =Serine!C30 -> NaN | T15: =Glycine!B30 -> NaN | U15: =Glycine!C30 -> NaN | V15: =Citrate!B30 -> 0.048783297 | W15: =Citrate!C30 -> 0.030907492 | X15: =Acetate!B30 -> 1 | Y15: =Acetate!C30 -> 0 | Z15: =Glycerol!B30 -> 0.024823164 | AA15: =Glycerol!C30 -> 0.0098466812 | AB15: =BCAAs!B30 -> NaN | AC15: =BCAAs!C30 -> NaN | AD15: ='6AAs'!B30 -> NaN | AE15: ='6AAs'!C30 -> NaN
... A18: 6AAs | B18: =Glucose!B33 -> 0 | C18: =Glucose!C33 -> 0 | D18: =Lactate!B33 -> 0 | E18: =Lactate!C33 -> 0 | F18: =Glutamine!B33 -> 0 | G18: =Glutamine!C33 -> 0 | H18: =Alanine!B33 -> 0 | I18: =Alanine!C33 -> 0 | J18: ='3HB'!B33 -> 0 | K18: ='3HB'!C33 -> 0 | L18: =Palmitate!B33 -> 0 | M18: =Palmitate!C33 -> 0 | N18: =Oleate!B33 -> 0 | O18: =Oleate!C33 -> 0 | P18: =Linoleate!B33 -> 0 | Q18: =Linoleate!C33 -> 0 | R18: =Serine!B33 -> 0 | S18: =Serine!C33 -> 0 | T18: =Glycine!B33 -> 0 | U18: =Glycine!C33 -> 0 | V18: =Citrate!B33 -> 0 | W18: =Citrate!C33 -> 0 | X18: =Acetate!B33 -> 0 | Y18: =Acetate!C33 -> 0 | Z18: =Glycerol!B33 -> 0 | AA18: =Glycerol!C33 -> 0 | AB18: =BCAAs!B33 -> 0 | AC18: =BCAAs!C33 -> 0 | AD18: ='6AAs'!B33 -> 1 | AE18: ='6AAs'!C33 -> 0
A20: Tissue malate
A21: Brain | B21: =Glucose!B37 -> 0.76561282 | C21: =Glucose!C37 -> 0.0051759707 | D21: =Lactate!B37 -> 0.35816666 | E21: =Lactate!C37 -> 0.024253984 | F21: =Glutamine!B37 -> 0.06678142 | G21: =Glutamine!C37 -> 0.0050527459 | H21: =Alanine!B37 -> 0.18917947 | I21: =Alanine!C37 -> 0.020534083 | J21: ='3HB'!B37 -> 0.035200095 | K21: ='3HB'!C37 -> 0.0097730625 | L21: =Palmitate!B37 -> 0.027903713 | M21: =Palmitate!C37 -> 0.006670133 | N21: =Oleate!B37 -> 0.064508945 | O21: =Oleate!C37 -> 0.01680696 | P21: =Linoleate!B37 -> 0.085541848 | Q21: =Linoleate!C37 -> 0.018173646 | R21: =Serine!B37 -> 0.012537287 | S21: =Serine!C37 -> 0.0029535612 | T21: =Glycine!B37 -> 0.0052682475 | U21: =Glycine!C37 -> 0.00028976296 | V21: =Citrate!B37 -> 0.02319108 | W21: =Citrate!C37 -> 0.0032838975 | X21: =Acetate!B37 -> 0.025974488 | Y21: =Acetate!C37 -> 0.0016273645 | Z21: =Glycerol!B37 -> 0.29015824 | AA21: =Glycerol!C37 -> 0.029995725 | AB21: =BCAAs!B37 -> 0.037180177 | AC21: =BCAAs!C37 -> 0.021559514 | AD21: ='6AAs'!B37 -> 0.017837734 | AE21: ='6AAs'!C37 -> 0.0020021326
A22: Muscle | B22: =Glucose!B38 -> 0.22203294 | C22: =Glucose!C38 -> 0.021853156 | D22: =Lactate!B38 -> 0.27843329 | E22: =Lactate!C38 -> 0.020357756 | F22: =Glutamine!B38 -> 0.085584097 | G22: =Glutamine!C38 -> 0.0083740121 | H22: =Alanine!B38 -> 0.04645518 | I22: =Alanine!C38 -> 0.0042337748 | J22: ='3HB'!B38 -> 0.034012689 | K22: ='3HB'!C38 -> 0.0067361288 | L22: =Palmitate!B38 -> 0.082958898 | M22: =Palmitate!C38 -> 0.0066700395 | N22: =Oleate!B38 -> 0.19223821 | O22: =Oleate!C38 -> 0.013836023 | P22: =Linoleate!B38 -> 0.19733173 | Q22: =Linoleate!C38 -> 0.023989048 | R22: =Serine!B38 -> 0.0012871939 | S22: =Serine!C38 -> 0.00077032317 | T22: =Glycine!B38 -> 0.0084609444 | U22: =Glycine!C38 -> 0.0062559398 | V22: =Citrate!B38 -> 0.0068080004 | W22: =Citrate!C38 -> 0.001076516 | X22: =Acetate!B38 -> 0.069665927 | Y22: =Acetate!C38 -> 0.0078244338 | Z22: =Glycerol!B38 -> 0.039045748 | AA22: =Glycerol!C38 -> 0.0080680431 | AB22: =BCAAs!B38 -> 0.04043372 | AC22: =BCAAs!C38 -> 0.00940332 | AD22: ='6AAs'!B38 -> 0.0063304415 | AE22: ='6AAs'!C38 -> 0.00060394997
A23: Kidney | B23: =Glucose!B39 -> 0.19661025 | C23: =Glucose!C39 -> 0.019798374 | D23: =Lactate!B39 -> 0.3730773 | E23: =Lactate!C39 -> 0.02702531 | F23: =Glutamine!B39 -> 0.13859344 | G23: =Glutamine!C39 -> 0.0029133276 | H23: =Alanine!B39 -> 0.095312153 | I23: =Alanine!C39 -> 0.030785214 | J23: ='3HB'!B39 -> 0.10300485 | K23: ='3HB'!C39 -> 0.019964899 | L23: =Palmitate!B39 -> 0.089435212 | M23: =Palmitate!C39 -> 0.012731395 | N23: =Oleate!B39 -> 0.15412532 | O23: =Oleate!C39 -> 0.012933937 | P23: =Linoleate!B39 -> 0.24462527 | Q23: =Linoleate!C39 -> 0.043487354 | R23: =Serine!B39 -> 0.0037951304 | S23: =Serine!C39 -> 0.00038070749 | T23: =Glycine!B39 -> 0.0059318481 | U23: =Glycine!C39 -> 0.0013793224 | V23: =Citrate!B39 -> 0.13468065 | W23: =Citrate!C39 -> 0.013410782 | X23: =Acetate!B39 -> 0.1363548 | Y23: =Acetate!C39 -> 0.011584535 | Z23: =Glycerol!B39 -> 0.095264688 | AA23: =Glycerol!C39 -> 0.0067521807 | AB23: =BCAAs!B39 -> 0.019316116 | AC23: =BCAAs!C39 -> 0.014463459 | AD23: ='6AAs'!B39 -> 0.014606754 | AE23: ='6AAs'!C39 -> 0.00055228299
A24: Liver | B24: =Glucose!B40 -> 0.16373151 | C24: =Glucose!C40 -> 0.0062916826 | D24: =Lactate!B40 -> 0.28632992 | E24: =Lactate!C40 -> 0.019785716 | F24: =Glutamine!B40 -> 0.1384273 | G24: =Glutamine!C40 -> 0.0053040966 | H24: =Alanine!B40 -> 0.16938273 | I24: =Alanine!C40 -> 0.013588275 | J24: ='3HB'!B40 -> 0.031647732 | K24: ='3HB'!C40 -> 0.0049018151 | L24: =Palmitate!B40 -> 0.055267836 | M24: =Palmitate!C40 -> 0.0083621516 | N24: =Oleate!B40 -> 0.10625112 | O24: =Oleate!C40 -> 0.012485496 | P24: =Linoleate!B40 -> 0.12131175 | Q24: =Linoleate!C40 -> 0.015027177 | R24: =Serine!B40 -> 0.01320758 | S24: =Serine!C40 -> 0.0022339462 | T24: =Glycine!B40 -> 0.0095118808 | U24: =Glycine!C40 -> 0.00075378808 | V24: =Citrate!B40 -> 0.011145258 | W24: =Citrate!C40 -> 0.00068664907 | X24: =Acetate!B40 -> 0.025143991 | Y24: =Acetate!C40 -> 0.002618401 | Z24: =Glycerol!B40 -> 0.070964917 | AA24: =Glycerol!C40 -> 0.0063061919 | AB24: =BCAAs!B40 -> 0.010246928 | AC24: =BCAAs!C40 -> 0.0084526941 | AD24: ='6AAs'!B40 -> 0.034201275 | AE24: ='6AAs'!C40 -> 0.0029160375
A25: Spleen | B25: =Glucose!B41 -> 0.11934019 | C25: =Glucose!C41 -> 0.011768687 | D25: =Lactate!B41 -> 0.22546748 | E25: =Lactate!C41 -> 0.028556907 | F25: =Glutamine!B41 -> 0.29255105 | G25: =Glutamine!C41 -> 0.032456399 | H25: =Alanine!B41 -> 0.054568251 | I25: =Alanine!C41 -> 0.0085323341 | J25: ='3HB'!B41 -> 0.097091256 | K25: ='3HB'!C41 -> 0.015586974 | L25: =Palmitate!B41 -> 0.11292043 | M25: =Palmitate!C41 -> 0.010520008 | N25: =Oleate!B41 -> 0.18401063 | O25: =Oleate!C41 -> 0.011087136 | P25: =Linoleate!B41 -> 0.2229915 | Q25: =Linoleate!C41 -> 0.030668345 | R25: =Serine!B41 -> 0.0050238802 | S25: =Serine!C41 -> 0.0017505434 | T25: =Glycine!B41 -> 0.0013319448 | U25: =Glycine!C41 -> 0.00042268571 | V25: =Citrate!B41 -> 0.0096731231 | W25: =Citrate!C41 -> 0.00091960073 | X25: =Acetate!B41 -> 0.16899683 | Y25: =Acetate!C41 -> 0.013671775 | Z25: =Glycerol!B41 -> 0.042887659 | AA25: =Glycerol!C41 -> 0.007563422 | AB25: =BCAAs!B41 -> 0.019742112 | AC25: =BCAAs!C41 -> 0.0051122172 | AD25: ='6AAs'!B41 -> 0.014516612 | AE25: ='6AAs'!C41 -> 0.0011130582
A26: Skin | B26: =Glucose!B42 -> NaN | C26: =Glucose!C42 -> NaN | D26: =Lactate!B42 -> NaN | E26: =Lactate!C42 -> NaN | F26: =Glutamine!B42 -> NaN | G26: =Glutamine!C42 -> NaN | H26: =Alanine!B42 -> 0.099382434 | I26: =Alanine!C42 -> 0.013545895 | J26: ='3HB'!B42 -> NaN | K26: ='3HB'!C42 -> NaN | L26: =Palmitate!B42 -> NaN | M26: =Palmitate!C42 -> NaN | N26: =Oleate!B42 -> NaN | O26: =Oleate!C42 -> NaN | P26: =Linoleate!B42 -> NaN | Q26: =Linoleate!C42 -> NaN | R26: =Serine!B42 -> NaN | S26: =Serine!C42 -> NaN | T26: =Glycine!B42 -> NaN | U26: =Glycine!C42 -> NaN | V26: =Citrate!B42 -> NaN | W26: =Citrate!C42 -> NaN | X26: =Acetate!B42 -> NaN | Y26: =Acetate!C42 -> NaN | Z26: =Glycerol!B42 -> NaN | AA26: =Glycerol!C42 -> NaN | AB26: =BCAAs!B42 -> NaN | AC26: =BCAAs!C42 -> NaN | AD26: ='6AAs'!B42 -> NaN | AE26: ='6AAs'!C42 -> NaN
A27: Pancreas | B27: =Glucose!B43 -> 0.14487504 | C27: =Glucose!C43 -> 0.012761019 | D27: =Lactate!B43 -> 0.27603439 | E27: =Lactate!C43 -> 0.023036349 | F27: =Glutamine!B43 -> 0.31676364 | G27: =Glutamine!C43 -> 0.080929279 | H27: =Alanine!B43 -> 0.18073727 | I27: =Alanine!C43 -> 0.01330555 | J27: ='3HB'!B43 -> 0.069228946 | K27: ='3HB'!C43 -> 0.0096104778 | L27: =Palmitate!B43 -> 0.062254174 | M27: =Palmitate!C43 -> 0.0067996397 | N27: =Oleate!B43 -> 0.1282116 | O27: =Oleate!C43 -> 0.012164627 | P27: =Linoleate!B43 -> 0.14395507 | Q27: =Linoleate!C43 -> 0.020707982 | R27: =Serine!B43 -> 0.0078467968 | S27: =Serine!C43 -> 0.0018632103 | T27: =Glycine!B43 -> 0.0012949594 | U27: =Glycine!C43 -> 0.0012949594 | V27: =Citrate!B43 -> 0.011246679 | W27: =Citrate!C43 -> 0.0014587534 | X27: =Acetate!B43 -> 0.06572319 | Y27: =Acetate!C43 -> 0.0037021094 | Z27: =Glycerol!B43 -> 0.044711153 | AA27: =Glycerol!C43 -> 0.0031951678 | AB27: =BCAAs!B43 -> 0.1858834 | AC27: =BCAAs!C43 -> 0.047000482 | AD27: ='6AAs'!B43 -> 0.039397706 | AE27: ='6AAs'!C43 -> 0.0034729437
A28: Lung | B28: =Glucose!B44 -> 0.20061321 | C28: =Glucose!C44 -> 0.018904113 | D28: =Lactate!B44 -> 0.27819317 | E28: =Lactate!C44 -> 0.021525989 | F28: =Glutamine!B44 -> 0.1076857 | G28: =Glutamine!C44 -> 0.0040766753 | H28: =Alanine!B44 -> 0.11680064 | I28: =Alanine!C44 -> 0.009793868 | J28: ='3HB'!B44 -> 0.052850932 | K28: ='3HB'!C44 -> 0.011553571 | L28: =Palmitate!B44 -> 0.11599291 | M28: =Palmitate!C44 -> 0.014678034 | N28: =Oleate!B44 -> 0.15573742 | O28: =Oleate!C44 -> 0.011367129 | P28: =Linoleate!B44 -> 0.16018712 | Q28: =Linoleate!C44 -> 0.028835847 | R28: =Serine!B44 -> 0.0011228137 | S28: =Serine!C44 -> 0.00031849942 | T28: =Glycine!B44 -> 0.0069024373 | U28: =Glycine!C44 -> 0.00071394336 | V28: =Citrate!B44 -> 0.015284526 | W28: =Citrate!C44 -> 0.00042283599 | X28: =Acetate!B44 -> 0.090976584 | Y28: =Acetate!C44 -> 0.0061507872 | Z28: =Glycerol!B44 -> 0.066292481 | AA28: =Glycerol!C44 -> 0.001754556 | AB28: =BCAAs!B44 -> 0.031236876 | AC28: =BCAAs!C44 -> 0.0085391361 | AD28: ='6AAs'!B44 -> 0.009373841 | AE28: ='6AAs'!C44 -> 0.0019890172
A29: Heart | B29: =Glucose!B45 -> 0.15863447 | C29: =Glucose!C45 -> 0.027413273 | D29: =Lactate!B45 -> 0.2263371 | E29: =Lactate!C45 -> 0.024551151 | F29: =Glutamine!B45 -> 0.02993779 | G29: =Glutamine!C45 -> 0.0034023044 | H29: =Alanine!B45 -> 0.022512695 | I29: =Alanine!C45 -> 0.0029400537 | J29: ='3HB'!B45 -> 0.054504815 | K29: ='3HB'!C45 -> 0.014123314 | L29: =Palmitate!B45 -> 0.15857088 | M29: =Palmitate!C45 -> 0.015951864 | N29: =Oleate!B45 -> 0.22114905 | O29: =Oleate!C45 -> 0.017583429 | P29: =Linoleate!B45 -> 0.21890929 | Q29: =Linoleate!C45 -> 0.023454781 | R29: =Serine!B45 -> 0.0015072125 | S29: =Serine!C45 -> 0.00074670958 | T29: =Glycine!B45 -> 0.0038361539 | U29: =Glycine!C45 -> 0.00028998931 | V29: =Citrate!B45 -> 0.0040066115 | W29: =Citrate!C45 -> 0.00016875322 | X29: =Acetate!B45 -> 0.10172025 | Y29: =Acetate!C45 -> 0.007861257 | Z29: =Glycerol!B45 -> 0.022045037 | AA29: =Glycerol!C45 -> 0.0041567183 | AB29: =BCAAs!B45 -> 0.012344043 | AC29: =BCAAs!C45 -> 0.0018564339 | AD29: ='6AAs'!B45 -> 0.0031817786 | AE29: ='6AAs'!C45 -> 0.00067676057
A30: gWAT | B30: =Glucose!B46 -> 0.15131952 | C30: =Glucose!C46 -> 0.013657844 | D30: =Lactate!B46 -> 0.24243186 | E30: =Lactate!C46 -> 0.02627428 | F30: =Glutamine!B46 -> 0.13486247 | G30: =Glutamine!C46 -> 0.0071252585 | H30: =Alanine!B46 -> 0.1100903 | I30: =Alanine!C46 -> 0.026225588 | J30: ='3HB'!B46 -> 0.025533078 | K30: ='3HB'!C46 -> 0.011463788 | L30: =Palmitate!B46 -> 0.038554865 | M30: =Palmitate!C46 -> 0.0083418703 | N30: =Oleate!B46 -> 0.11996903 | O30: =Oleate!C46 -> 0.017157743 | P30: =Linoleate!B46 -> 0.071907837 | Q30: =Linoleate!C46 -> 0.019240928 | R30: =Serine!B46 -> 0.00025526454 | S30: =Serine!C46 -> 0.00025526454 | T30: =Glycine!B46 -> 0.0019997575 | U30: =Glycine!C46 -> 0.00019233791 | V30: =Citrate!B46 -> 0.021405082 | W30: =Citrate!C46 -> 0.018643373 | X30: =Acetate!B46 -> 0.04373612 | Y30: =Acetate!C46 -> 0.0058791392 | Z30: =Glycerol!B46 -> 0.020312183 | AA30: =Glycerol!C46 -> 0.010643036 | AB30: =BCAAs!B46 -> 0.024369896 | AC30: =BCAAs!C46 -> 0.013768776 | AD30: ='6AAs'!B46 -> 0.018029947 | AE30: ='6AAs'!C46 -> #DIV/0!
A31: iWAT | B31: =Glucose!B47 -> 0.14825689 | C31: =Glucose!C47 -> 0.010716261 | D31: =Lactate!B47 -> 0.22277835 | E31: =Lactate!C47 -> 0.013239582 | F31: =Glutamine!B47 -> 0.13709657 | G31: =Glutamine!C47 -> 0.0058542029 | H31: =Alanine!B47 -> NaN | I31: =Alanine!C47 -> NaN | J31: ='3HB'!B47 -> NaN | K31: ='3HB'!C47 -> NaN | L31: =Palmitate!B47 -> 0.028004037 | M31: =Palmitate!C47 -> 0.0021773277 | N31: =Oleate!B47 -> NaN | O31: =Oleate!C47 -> NaN | P31: =Linoleate!B47 -> 0.052820379 | Q31: =Linoleate!C47 -> 0.016527451 | R31: =Serine!B47 -> NaN | S31: =Serine!C47 -> NaN | T31: =Glycine!B47 -> 0.0026596807 | U31: =Glycine!C47 -> 0.001108093 | V31: =Citrate!B47 -> NaN | W31: =Citrate!C47 -> NaN | X31: =Acetate!B47 -> 0.061658051 | Y31: =Acetate!C47 -> 0.005575044 | Z31: =Glycerol!B47 -> NaN | AA31: =Glycerol!C47 -> NaN | AB31: =BCAAs!B47 -> NaN | AC31: =BCAAs!C47 -> NaN | AD31: ='6AAs'!B47 -> NaN | AE31: ='6AAs'!C47 -> NaN
A32: Small intestine | B32: =Glucose!B48 -> 0.12626288 | C32: =Glucose!C48 -> 0.013997233 | D32: =Lactate!B48 -> 0.27001266 | E32: =Lactate!C48 -> 0.037546749 | F32: =Glutamine!B48 -> 0.29342298 | G32: =Glutamine!C48 -> 0.017737385 | H32: =Alanine!B48 -> 0.080265848 | I32: =Alanine!C48 -> 0.014696912 | J32: ='3HB'!B48 -> 0.11660952 | K32: ='3HB'!C48 -> 0.023457388 | L32: =Palmitate!B48 -> 0.089379683 | M32: =Palmitate!C48 -> 0.014454397 | N32: =Oleate!B48 -> 0.12233628 | O32: =Oleate!C48 -> 0.022059721 | P32: =Linoleate!B48 -> 0.18100458 | Q32: =Linoleate!C48 -> 0.038720187 | R32: =Serine!B48 -> 0.0020722941 | S32: =Serine!C48 -> 0.0010511312 | T32: =Glycine!B48 -> 0.0036043197 | U32: =Glycine!C48 -> 0.0011364058 | V32: =Citrate!B48 -> 0.014302456 | W32: =Citrate!C48 -> 0.0015445606 | X32: =Acetate!B48 -> 0.087309322 | Y32: =Acetate!C48 -> 0.0067524723 | Z32: =Glycerol!B48 -> 0.042194242 | AA32: =Glycerol!C48 -> 0.0086332382 | AB32: =BCAAs!B48 -> 0.032523651 | AC32: =BCAAs!C48 -> 0.0087315436 | AD32: ='6AAs'!B48 -> 0.014700472 | AE32: ='6AAs'!C48 -> 0.00075887057
... A35: Bone | B35: =Glucose!B51 -> NaN | C35: =Glucose!C51 -> NaN | D35: =Lactate!B51 -> NaN | E35: =Lactate!C51 -> NaN | F35: =Glutamine!B51 -> NaN | G35: =Glutamine!C51 -> NaN | H35: =Alanine!B51 -> NaN | I35: =Alanine!C51 -> NaN | J35: ='3HB'!B51 -> NaN | K35: ='3HB'!C51 -> NaN | L35: =Palmitate!B51 -> NaN | M35: =Palmitate!C51 -> NaN | N35: =Oleate!B51 -> NaN | O35: =Oleate!C51 -> NaN | P35: =Linoleate!B51 -> NaN | Q35: =Linoleate!C51 -> NaN | R35: =Serine!B51 -> NaN | S35: =Serine!C51 -> NaN | T35: =Glycine!B51 -> NaN | U35: =Glycine!C51 -> NaN | V35: =Citrate!B51 -> NaN | W35: =Citrate!C51 -> NaN | X35: =Acetate!B51 -> NaN | Y35: =Acetate!C51 -> NaN | Z35: =Glycerol!B51 -> NaN | AA35: =Glycerol!C51 -> NaN | AB35: =BCAAs!B51 -> NaN | AC35: =BCAAs!C51 -> NaN | AD35: ='6AAs'!B51 -> NaN | AE35: ='6AAs'!C51 -> NaN
A37: Tissue succinate
A38: Brain | B38: =Glucose!B54 -> 0.76340271 | C38: =Glucose!C54 -> 0.0067117172 | D38: =Lactate!B54 -> 0.35843218 | E38: =Lactate!C54 -> 0.023398857 | F38: =Glutamine!B54 -> 0.062177908 | G38: =Glutamine!C54 -> 0.0060840976 | H38: =Alanine!B54 -> 0.20251479 | I38: =Alanine!C54 -> 0.021153315 | J38: ='3HB'!B54 -> 0.029252885 | K38: ='3HB'!C54 -> 0.009172975 | L38: =Palmitate!B54 -> 0.028099848 | M38: =Palmitate!C54 -> 0.0073255185 | N38: =Oleate!B54 -> 0.055392189 | O38: =Oleate!C54 -> 0.013488153 | P38: =Linoleate!B54 -> 0.081756882 | Q38: =Linoleate!C54 -> 0.020405652 | R38: =Serine!B54 -> 0.011439853 | S38: =Serine!C54 -> 0.0048157919 | T38: =Glycine!B54 -> 0.0037381761 | U38: =Glycine!C54 -> 0.0012244057 | V38: =Citrate!B54 -> 0.023631953 | W38: =Citrate!C54 -> 0.003098097 | X38: =Acetate!B54 -> 0.024691175 | Y38: =Acetate!C54 -> 0.0026124788 | Z38: =Glycerol!B54 -> 0.2227251 | AA38: =Glycerol!C54 -> 0.071199673 | AB38: =BCAAs!B54 -> 0.017237217 | AC38: =BCAAs!C54 -> 0.0015762032 | AD38: ='6AAs'!B54 -> 0.014943689 | AE38: ='6AAs'!C54 -> 0.0026170986
A39: Muscle | B39: =Glucose!B55 -> 0.22450274 | C39: =Glucose!C55 -> 0.027950166 | D39: =Lactate!B55 -> 0.27516619 | E39: =Lactate!C55 -> 0.022587702 | F39: =Glutamine!B55 -> 0.082361952 | G39: =Glutamine!C55 -> 0.0070854432 | H39: =Alanine!B55 -> 0.046945146 | I39: =Alanine!C55 -> 0.0036425169 | J39: ='3HB'!B55 -> 0.034108579 | K39: ='3HB'!C55 -> 0.0058965597 | L39: =Palmitate!B55 -> 0.086348462 | M39: =Palmitate!C55 -> 0.00770769 | N39: =Oleate!B55 -> 0.18572061 | O39: =Oleate!C55 -> 0.0131057 | P39: =Linoleate!B55 -> 0.21387832 | Q39: =Linoleate!C55 -> 0.023086535 | R39: =Serine!B55 -> 0.0016473357 | S39: =Serine!C55 -> 0.0004845279 | T39: =Glycine!B55 -> 0.0010408813 | U39: =Glycine!C55 -> 0.00024331351 | V39: =Citrate!B55 -> 0.0045727014 | W39: =Citrate!C55 -> 0.0012760537 | X39: =Acetate!B55 -> 0.073196169 | Y39: =Acetate!C55 -> 0.012448346 | Z39: =Glycerol!B55 -> 0.036688198 | AA39: =Glycerol!C55 -> 0.0064126018 | AB39: =BCAAs!B55 -> 0.043840158 | AC39: =BCAAs!C55 -> 0.0073451565 | AD39: ='6AAs'!B55 -> 0.0041076765 | AE39: ='6AAs'!C55 -> 0.0017641605
A40: Kidney | B40: =Glucose!B56 -> 0.19689336 | C40: =Glucose!C56 -> 0.024103523 | D40: =Lactate!B56 -> 0.38280061 | E40: =Lactate!C56 -> 0.03039479 | F40: =Glutamine!B56 -> 0.15185821 | G40: =Glutamine!C56 -> 0.0045265581 | H40: =Alanine!B56 -> 0.10199821 | I40: =Alanine!C56 -> 0.018842783 | J40: ='3HB'!B56 -> 0.1148422 | K40: ='3HB'!C56 -> 0.018677893 | L40: =Palmitate!B56 -> 0.094538686 | M40: =Palmitate!C56 -> 0.014933863 | N40: =Oleate!B56 -> 0.17359946 | O40: =Oleate!C56 -> 0.016242493 | P40: =Linoleate!B56 -> 0.33314312 | Q40: =Linoleate!C56 -> 0.05729144 | R40: =Serine!B56 -> 0.0036822721 | S40: =Serine!C56 -> 2.6605959e-05 | T40: =Glycine!B56 -> 0.0045410906 | U40: =Glycine!C56 -> 0.0013087707 | V40: =Citrate!B56 -> 0.1638037 | W40: =Citrate!C56 -> 0.0066677983 | X40: =Acetate!B56 -> 0.13756858 | Y40: =Acetate!C56 -> 0.014675893 | Z40: =Glycerol!B56 -> 0.091666787 | AA40: =Glycerol!C56 -> 0.0058553673 | AB40: =BCAAs!B56 -> 0.020505671 | AC40: =BCAAs!C56 -> 0.014530693 | AD40: ='6AAs'!B56 -> 0.016199219 | AE40: ='6AAs'!C56 -> 0.0014702936
A41: Liver | B41: =Glucose!B57 -> 0.1586676 | C41: =Glucose!C57 -> 0.0099547719 | D41: =Lactate!B57 -> 0.29996173 | E41: =Lactate!C57 -> 0.017502643 | F41: =Glutamine!B57 -> 0.16706629 | G41: =Glutamine!C57 -> 0.0084558956 | H41: =Alanine!B57 -> 0.17362146 | I41: =Alanine!C57 -> 0.013123926 | J41: ='3HB'!B57 -> 0.030750012 | K41: ='3HB'!C57 -> 0.0051628212 | L41: =Palmitate!B57 -> 0.06212656 | M41: =Palmitate!C57 -> 0.010292512 | N41: =Oleate!B57 -> 0.1046541 | O41: =Oleate!C57 -> 0.0091373028 | P41: =Linoleate!B57 -> 0.14970118 | Q41: =Linoleate!C57 -> 0.016390809 | R41: =Serine!B57 -> 0.011495236 | S41: =Serine!C57 -> 0.0025991302 | T41: =Glycine!B57 -> 0.00929003 | U41: =Glycine!C57 -> 0.00089854262 | V41: =Citrate!B57 -> 0.0093173145 | W41: =Citrate!C57 -> 0.0012564412 | X41: =Acetate!B57 -> 0.022168809 | Y41: =Acetate!C57 -> 0.0038538797 | Z41: =Glycerol!B57 -> 0.068686853 | AA41: =Glycerol!C57 -> 0.0037386267 | AB41: =BCAAs!B57 -> 0.014385607 | AC41: =BCAAs!C57 -> 0.0091601742 | AD41: ='6AAs'!B57 -> 0.046733723 | AE41: ='6AAs'!C57 -> 0.00455339
A42: Spleen | B42: =Glucose!B58 -> 0.10984356 | C42: =Glucose!C58 -> 0.012929741 | D42: =Lactate!B58 -> 0.21168849 | E42: =Lactate!C58 -> 0.028960385 | F42: =Glutamine!B58 -> 0.27621576 | G42: =Glutamine!C58 -> 0.02514382 | H42: =Alanine!B58 -> 0.053157562 | I42: =Alanine!C58 -> 0.008859247 | J42: ='3HB'!B58 -> 0.10565625 | K42: ='3HB'!C58 -> 0.016784387 | L42: =Palmitate!B58 -> 0.11379975 | M42: =Palmitate!C58 -> 0.013383117 | N42: =Oleate!B58 -> 0.18656471 | O42: =Oleate!C58 -> 0.013039859 | P42: =Linoleate!B58 -> 0.22612718 | Q42: =Linoleate!C58 -> 0.034936021 | R42: =Serine!B58 -> 0.0022200292 | S42: =Serine!C58 -> 0.00037061159 | T42: =Glycine!B58 -> 0.0012282144 | U42: =Glycine!C58 -> 0.00018859789 | V42: =Citrate!B58 -> 0.0066840428 | W42: =Citrate!C58 -> 0.0011401202 | X42: =Acetate!B58 -> 0.168892 | Y42: =Acetate!C58 -> 0.019001685 | Z42: =Glycerol!B58 -> 0.037278704 | AA42: =Glycerol!C58 -> 0.0092465977 | AB42: =BCAAs!B58 -> 0.021974191 | AC42: =BCAAs!C58 -> 0.0027207534 | AD42: ='6AAs'!B58 -> 0.015128136 | AE42: ='6AAs'!C58 -> 0.0010467068
A43: Skin | B43: =Glucose!B59 -> NaN | C43: =Glucose!C59 -> NaN | D43: =Lactate!B59 -> NaN | E43: =Lactate!C59 -> NaN | F43: =Glutamine!B59 -> NaN | G43: =Glutamine!C59 -> NaN | H43: =Alanine!B59 -> 0.081770366 | I43: =Alanine!C59 -> 0.011087674 | J43: ='3HB'!B59 -> NaN | K43: ='3HB'!C59 -> NaN | L43: =Palmitate!B59 -> NaN | M43: =Palmitate!C59 -> NaN | N43: =Oleate!B59 -> NaN | O43: =Oleate!C59 -> NaN | P43: =Linoleate!B59 -> NaN | Q43: =Linoleate!C59 -> NaN | R43: =Serine!B59 -> NaN | S43: =Serine!C59 -> NaN | T43: =Glycine!B59 -> NaN | U43: =Glycine!C59 -> NaN | V43: =Citrate!B59 -> NaN | W43: =Citrate!C59 -> NaN | X43: =Acetate!B59 -> NaN | Y43: =Acetate!C59 -> NaN | Z43: =Glycerol!B59 -> NaN | AA43: =Glycerol!C59 -> NaN | AB43: =BCAAs!B59 -> NaN | AC43: =BCAAs!C59 -> NaN | AD43: ='6AAs'!B59 -> NaN | AE43: ='6AAs'!C59 -> NaN
A44: Pancreas | B44: =Glucose!B60 -> 0.14368616 | C44: =Glucose!C60 -> 0.015144614 | D44: =Lactate!B60 -> 0.26118324 | E44: =Lactate!C60 -> 0.021779131 | F44: =Glutamine!B60 -> 0.36098142 | G44: =Glutamine!C60 -> 0.08716525 | H44: =Alanine!B60 -> 0.14987352 | I44: =Alanine!C60 -> 0.010241704 | J44: ='3HB'!B60 -> 0.073174307 | K44: ='3HB'!C60 -> 0.0096953993 | L44: =Palmitate!B60 -> 0.067284973 | M44: =Palmitate!C60 -> 0.010251122 | N44: =Oleate!B60 -> 0.10672242 | O44: =Oleate!C60 -> 0.012564626 | P44: =Linoleate!B60 -> 0.15674892 | Q44: =Linoleate!C60 -> 0.023917826 | R44: =Serine!B60 -> 0.0059246517 | S44: =Serine!C60 -> 0.0020608487 | T44: =Glycine!B60 -> 0.00042918502 | U44: =Glycine!C60 -> 9.625932e-05 | V44: =Citrate!B60 -> 0.012791899 | W44: =Citrate!C60 -> 0.00031698076 | X44: =Acetate!B60 -> 0.065364309 | Y44: =Acetate!C60 -> 0.0086948756 | Z44: =Glycerol!B60 -> 0.040706992 | AA44: =Glycerol!C60 -> 0.0024467445 | AB44: =BCAAs!B60 -> 0.19470416 | AC44: =BCAAs!C60 -> 0.038961983 | AD44: ='6AAs'!B60 -> 0.046014642 | AE44: ='6AAs'!C60 -> 0.0023634209
A45: Lung | B45: =Glucose!B61 -> 0.15459785 | C45: =Glucose!C61 -> 0.017971343 | D45: =Lactate!B61 -> 0.21269074 | E45: =Lactate!C61 -> 0.023110749 | F45: =Glutamine!B61 -> 0.077895968 | G45: =Glutamine!C61 -> 0.016929211 | H45: =Alanine!B61 -> 0.079468311 | I45: =Alanine!C61 -> 0.0081216026 | J45: ='3HB'!B61 -> 0.038208647 | K45: ='3HB'!C61 -> 0.01303888 | L45: =Palmitate!B61 -> 0.1353137 | M45: =Palmitate!C61 -> 0.013473735 | N45: =Oleate!B61 -> 0.1542664 | O45: =Oleate!C61 -> 0.017262954 | P45: =Linoleate!B61 -> 0.16591618 | Q45: =Linoleate!C61 -> 0.03018505 | R45: =Serine!B61 -> 0.0012071992 | S45: =Serine!C61 -> 0.00093874802 | T45: =Glycine!B61 -> 0.0023610877 | U45: =Glycine!C61 -> 0.00030163964 | V45: =Citrate!B61 -> 0.011515108 | W45: =Citrate!C61 -> 0.0020578911 | X45: =Acetate!B61 -> 0.078620761 | Y45: =Acetate!C61 -> 0.013600078 | Z45: =Glycerol!B61 -> 0.051302009 | AA45: =Glycerol!C61 -> 0.0040407557 | AB45: =BCAAs!B61 -> 0.026913011 | AC45: =BCAAs!C61 -> 0.0066711354 | AD45: ='6AAs'!B61 -> 0.007716465 | AE45: ='6AAs'!C61 -> 0.0024363485
A46: Heart | B46: =Glucose!B62 -> 0.1645011 | C46: =Glucose!C62 -> 0.030396016 | D46: =Lactate!B62 -> 0.23125104 | E46: =Lactate!C62 -> 0.027125771 | F46: =Glutamine!B62 -> 0.019876869 | G46: =Glutamine!C62 -> 0.0014456429 | H46: =Alanine!B62 -> 0.021023674 | I46: =Alanine!C62 -> 0.0029723118 | J46: ='3HB'!B62 -> 0.053643365 | K46: ='3HB'!C62 -> 0.012440406 | L46: =Palmitate!B62 -> 0.17317477 | M46: =Palmitate!C62 -> 0.018120235 | N46: =Oleate!B62 -> 0.24621537 | O46: =Oleate!C62 -> 0.017137055 | P46: =Linoleate!B62 -> 0.24505069 | Q46: =Linoleate!C62 -> 0.026410025 | R46: =Serine!B62 -> 0.0013639083 | S46: =Serine!C62 -> 0.00060749038 | T46: =Glycine!B62 -> 0.0031988112 | U46: =Glycine!C62 -> 1.6764119e-05 | V46: =Citrate!B62 -> 0.0041492689 | W46: =Citrate!C62 -> 0.00043794397 | X46: =Acetate!B62 -> 0.099641125 | Y46: =Acetate!C62 -> 0.0093929042 | Z46: =Glycerol!B62 -> 0.019678796 | AA46: =Glycerol!C62 -> 0.0042459383 | AB46: =BCAAs!B62 -> 0.013775677 | AC46: =BCAAs!C62 -> 0.0010457424 | AD46: ='6AAs'!B62 -> 0.0056493534 | AE46: ='6AAs'!C62 -> 0.00069859672
...

Sheet Refed
B1: Glucose infusion | D1: Lactate infusion | F1: Glutamine infusion | H1: Alanine Infusion | J1: 3HB infusion | L1: Palmitic acid infusion | N1: Oleic acid infusion | P1: Linoleic acid infusion | R1: Seine infusion | T1: Glycine infusion | V1: Citrate infusion | X1: Acetate infusion | Z1: Glycerol infusion | AB1: BCAAs infusion | AD1: 6AAs infusion
B2: Mean | C2: SEM | D2: Mean | E2: SEM | F2: Mean | G2: SEM | H2: Mean | I2: SEM | J2: Mean | K2: SEM | L2: Mean | M2: SEM | N2: Mean | O2: SEM | P2: Mean | Q2: SEM | R2: Mean | S2: SEM | T2: Mean | U2: SEM | V2: Mean | W2: SEM | X2: Mean | Y2: SEM | Z2: Mean | AA2: SEM | AB2: Mean | AC2: SEM | AD2: Mean | AE2: SEM
A3: Serum
A4: glucose | B4: =Glucose!B99 -> 1 | C4: =Glucose!C99 -> 0 | D4: =Lactate!B99 -> 0.18055056 | E4: =Lactate!C99 -> 0.033587339 | F4: =Glutamine!B99 -> 0.04076097 | G4: =Glutamine!C99 -> 0.0097451 | H4: =Alanine!B99 -> 0.060576256 | I4: =Alanine!C99 -> 0.012189605 | J4: ='3HB'!B99 -> 0.0031831372 | K4: ='3HB'!C99 -> 0.00023054045 | L4: =Palmitate!B99 -> 0.0047080477 | M4: =Palmitate!C99 -> 0.00076595396 | N4: =Oleate!B99 -> 0.025233255 | O4: =Oleate!C99 -> 0.006914697 | P4: =Linoleate!B99 -> 0.041605183 | Q4: =Linoleate!C99 -> 0.0056100614 | R4: =Serine!B99 -> 0.016000517 | S4: =Serine!C99 -> 0.00093592485 | T4: =Glycine!B99 -> 0.0023734534 | U4: =Glycine!C99 -> 0.00098479692 | V4: =Citrate!B99 -> 0.011178664 | W4: =Citrate!C99 -> 0.0019324498 | X4: =Acetate!B99 -> 0.015763378 | Y4: =Acetate!C99 -> 0.0033034608 | Z4: =Glycerol!B99 -> 0.05774472 | AA4: =Glycerol!C99 -> 0.0050738728 | AB4: =BCAAs!B99 -> 0.0067179612 | AC4: =BCAAs!C99 -> 0.00092016352 | AD4: ='6AAs'!B99 -> 0.019262513 | AE4: ='6AAs'!C99 -> 0.0030763023
A5: lactate | B5: =Glucose!B100 -> 0.79297216 | C5: =Glucose!C100 -> 0.018041733 | D5: =Lactate!B100 -> 1 | E5: =Lactate!C100 -> 4.1114672e-17 | F5: =Glutamine!B100 -> 0.038142502 | G5: =Glutamine!C100 -> 0.015995018 | H5: =Alanine!B100 -> 0.11709725 | I5: =Alanine!C100 -> 0.017959478 | J5: ='3HB'!B100 -> 0.0049152531 | K5: ='3HB'!C100 -> 0.00046013907 | L5: =Palmitate!B100 -> 0.012401563 | M5: =Palmitate!C100 -> 0.0025145358 | N5: =Oleate!B100 -> 0.026423631 | O5: =Oleate!C100 -> 0.0063613878 | P5: =Linoleate!B100 -> 0.049747238 | Q5: =Linoleate!C100 -> 0.0057814284 | R5: =Serine!B100 -> 0.010549309 | S5: =Serine!C100 -> 0.0005012736 | T5: =Glycine!B100 -> 0.0065912855 | U5: =Glycine!C100 -> 0.00086046263 | V5: =Citrate!B100 -> 0.0076884796 | W5: =Citrate!C100 -> 0.00054374865 | X5: =Acetate!B100 -> 0.022803839 | Y5: =Acetate!C100 -> 0.0051815557 | Z5: =Glycerol!B100 -> 0.081802782 | AA5: =Glycerol!C100 -> 0.0065994703 | AB5: =BCAAs!B100 -> 0.014029039 | AC5: =BCAAs!C100 -> 0.000491532 | AD5: ='6AAs'!B100 -> 0.0213763 | AE5: ='6AAs'!C100 -> 0.0019796528
A6: glutamine | B6: =Glucose!B101 -> 0.21493543 | C6: =Glucose!C101 -> 0.020644665 | D6: =Lactate!B101 -> 0.25455363 | E6: =Lactate!C101 -> 0.027189506 | F6: =Glutamine!B101 -> 1 | G6: =Glutamine!C101 -> 0 | H6: =Alanine!B101 -> 0.086455207 | I6: =Alanine!C101 -> 0.0037728693 | J6: ='3HB'!B101 -> 0.011963776 | K6: ='3HB'!C101 -> 0.00023634494 | L6: =Palmitate!B101 -> 0.027085385 | M6: =Palmitate!C101 -> 0.0035462193 | N6: =Oleate!B101 -> 0.078115707 | O6: =Oleate!C101 -> 0.016866609 | P6: =Linoleate!B101 -> 0.10010959 | Q6: =Linoleate!C101 -> 0.0066001344 | R6: =Serine!B101 -> 0.0031266305 | S6: =Serine!C101 -> 0.00086095763 | T6: =Glycine!B101 -> 0.00058724885 | U6: =Glycine!C101 -> 0.00058724885 | V6: =Citrate!B101 -> 0.020221217 | W6: =Citrate!C101 -> 0.0033940371 | X6: =Acetate!B101 -> 0.047727901 | Y6: =Acetate!C101 -> 0.0063297592 | Z6: =Glycerol!B101 -> 0.012003952 | AA6: =Glycerol!C101 -> 0.0019638973 | AB6: =BCAAs!B101 -> 0.024326925 | AC6: =BCAAs!C101 -> 0.0014129225 | AD6: ='6AAs'!B101 -> 0.024039876 | AE6: ='6AAs'!C101 -> 0.0036646332
A7: alanine | B7: =Glucose!B102 -> 0.45928663 | C7: =Glucose!C102 -> 0.042693472 | D7: =Lactate!B102 -> 0.48732737 | E7: =Lactate!C102 -> 0.026587595 | F7: =Glutamine!B102 -> 0.030042665 | G7: =Glutamine!C102 -> 0.018332514 | H7: =Alanine!B102 -> 1 | I7: =Alanine!C102 -> 0 | J7: ='3HB'!B102 -> 0.0033673826 | K7: ='3HB'!C102 -> 8.6513131e-06 | L7: =Palmitate!B102 -> 0.0021738773 | M7: =Palmitate!C102 -> 0.00151754 | N7: =Oleate!B102 -> 0.0059410775 | O7: =Oleate!C102 -> 0.0027904409 | P7: =Linoleate!B102 -> 0.011765337 | Q7: =Linoleate!C102 -> 0.0048533385 | R7: =Serine!B102 -> 0.0035145015 | S7: =Serine!C102 -> 0.00080642907 | T7: =Glycine!B102 -> 0.002447754 | U7: =Glycine!C102 -> 0.00050407328 | V7: =Citrate!B102 -> 0.0057835312 | W7: =Citrate!C102 -> 0.0006272533 | X7: =Acetate!B102 -> 0.012849124 | Y7: =Acetate!C102 -> 0.0029551156 | Z7: =Glycerol!B102 -> 0.032534532 | AA7: =Glycerol!C102 -> 0.0091780514 | AB7: =BCAAs!B102 -> 0.0021915923 | AC7: =BCAAs!C102 -> 0.0020151088 | AD7: ='6AAs'!B102 -> 0.023156131 | AE7: ='6AAs'!C102 -> 0.0050000365
A8: 3-hydroxybutyrate | B8: =Glucose!B103 -> 0.027177727 | C8: =Glucose!C103 -> 0.010080348 | D8: =Lactate!B103 -> 0.01439621 | E8: =Lactate!C103 -> 0.0079714714 | F8: =Glutamine!B103 -> 0.0014972798 | G8: =Glutamine!C103 -> 0.0028418399 | H8: =Alanine!B103 -> 0.0079221121 | I8: =Alanine!C103 -> 0.0051971734 | J8: ='3HB'!B103 -> 1 | K8: ='3HB'!C103 -> 0 | L8: =Palmitate!B103 -> 0.021037594 | M8: =Palmitate!C103 -> 0.0071967152 | N8: =Oleate!B103 -> 0.14965176 | O8: =Oleate!C103 -> 0.017206343 | P8: =Linoleate!B103 -> 0.19484424 | Q8: =Linoleate!C103 -> 0.034609606 | R8: =Serine!B103 -> 0 | S8: =Serine!C103 -> 0 | T8: =Glycine!B103 -> 0 | U8: =Glycine!C103 -> 0 | V8: =Citrate!B103 -> 0.00014728143 | W8: =Citrate!C103 -> 0.00014728143 | X8: =Acetate!B103 -> 0.0051099162 | Y8: =Acetate!C103 -> 0.0010203757 | Z8: =Glycerol!B103 -> 0 | AA8: =Glycerol!C103 -> 0 | AB8: =BCAAs!B103 -> 0.028816849 | AC8: =BCAAs!C103 -> 0.0023332794 | AD8: ='6AAs'!B103 -> 0.067843819 | AE8: ='6AAs'!C103 -> 0.026521732
A9: palmitic acid | B9: =Glucose!B104 -> 0.012473429 | C9: =Glucose!C104 -> 0.0041540596 | D9: =Lactate!B104 -> 0.00089237628 | E9: =Lactate!C104 -> 0.00046340844 | F9: =Glutamine!B104 -> 0.00015068407 | G9: =Glutamine!C104 -> 0.00021666199 | H9: =Alanine!B104 -> 0 | I9: =Alanine!C104 -> 0 | J9: ='3HB'!B104 -> 4.482992e-05 | K9: ='3HB'!C104 -> 1.4427661e-05 | L9: =Palmitate!B104 -> 1 | M9: =Palmitate!C104 -> 0 | N9: =Oleate!B104 -> 0.0013612644 | O9: =Oleate!C104 -> 0.0010628485 | P9: =Linoleate!B104 -> 0.003484386 | Q9: =Linoleate!C104 -> 0.0014913388 | R9: =Serine!B104 -> 0 | S9: =Serine!C104 -> 0 | T9: =Glycine!B104 -> 0.0013011224 | U9: =Glycine!C104 -> 0.0013011224 | V9: =Citrate!B104 -> 0.00013615256 | W9: =Citrate!C104 -> 6.9458331e-05 | X9: =Acetate!B104 -> 0.0017239297 | Y9: =Acetate!C104 -> 0.00060563683 | Z9: =Glycerol!B104 -> 7.9788633e-05 | AA9: =Glycerol!C104 -> 5.3888974e-05 | AB9: =BCAAs!B104 -> 6.8309032e-05 | AC9: =BCAAs!C104 -> 5.0139114e-05 | AD9: ='6AAs'!B104 -> 0.0011988803 | AE9: ='6AAs'!C104 -> 0.00098197887
A10: oleic acid | B10: =Glucose!B105 -> 0.0013486988 | C10: =Glucose!C105 -> 0.00051420859 | D10: =Lactate!B105 -> 0.00059119932 | E10: =Lactate!C105 -> 0.00048194942 | F10: =Glutamine!B105 -> 0.00010162326 | G10: =Glutamine!C105 -> 0.00020721587 | H10: =Alanine!B105 -> 0 | I10: =Alanine!C105 -> 0 | J10: ='3HB'!B105 -> 0 | K10: ='3HB'!C105 -> 0 | L10: =Palmitate!B105 -> 0.0087538364 | M10: =Palmitate!C105 -> 0.0021609049 | N10: =Oleate!B105 -> 1 | O10: =Oleate!C105 -> 0 | P10: =Linoleate!B105 -> 0.0053430755 | Q10: =Linoleate!C105 -> 0.0016293773 | R10: =Serine!B105 -> 6.4238125e-05 | S10: =Serine!C105 -> 3.232974e-05 | T10: =Glycine!B105 -> 0 | U10: =Glycine!C105 -> 0 | V10: =Citrate!B105 -> 0 | W10: =Citrate!C105 -> 0 | X10: =Acetate!B105 -> 9.9284473e-05 | Y10: =Acetate!C105 -> 5.9798546e-05 | Z10: =Glycerol!B105 -> 0 | AA10: =Glycerol!C105 -> 0 | AB10: =BCAAs!B105 -> 8.9880319e-05 | AC10: =BCAAs!C105 -> 5.6849588e-05 | AD10: ='6AAs'!B105 -> 0.00048469937 | AE10: ='6AAs'!C105 -> 0.00027629647
A11: linoleic acid | B11: =Glucose!B106 -> 0.00011182799 | C11: =Glucose!C106 -> 0.00011182799 | D11: =Lactate!B106 -> 0.00035117527 | E11: =Lactate!C106 -> 0.00035117527 | F11: =Glutamine!B106 -> 2.9378947e-05 | G11: =Glutamine!C106 -> 8.8136841e-05 | H11: =Alanine!B106 -> 0 | I11: =Alanine!C106 -> 0 | J11: ='3HB'!B106 -> 0 | K11: ='3HB'!C106 -> 0 | L11: =Palmitate!B106 -> 0.0017928983 | M11: =Palmitate!C106 -> 0.0017928983 | N11: =Oleate!B106 -> 0 | O11: =Oleate!C106 -> 0 | P11: =Linoleate!B106 -> 1 | Q11: =Linoleate!C106 -> 0 | R11: =Serine!B106 -> 0 | S11: =Serine!C106 -> 0 | T11: =Glycine!B106 -> 0 | U11: =Glycine!C106 -> 0 | V11: =Citrate!B106 -> 0 | W11: =Citrate!C106 -> 0 | X11: =Acetate!B106 -> 0.00017923817 | Y11: =Acetate!C106 -> 0.00017923817 | Z11: =Glycerol!B106 -> 0 | AA11: =Glycerol!C106 -> 0 | AB11: =BCAAs!B106 -> 0 | AC11: =BCAAs!C106 -> 0 | AD11: ='6AAs'!B106 -> 0 | AE11: ='6AAs'!C106 -> 0
A12: serine | B12: =Glucose!B107 -> 0.079432354 | C12: =Glucose!C107 -> 0.017316419 | D12: =Lactate!B107 -> 0.014371063 | E12: =Lactate!C107 -> 0.0040163824 | F12: =Glutamine!B107 -> 0.0044529846 | G12: =Glutamine!C107 -> 0.0055637083 | H12: =Alanine!B107 -> 0.0011794364 | I12: =Alanine!C107 -> 0.0011794364 | J12: ='3HB'!B107 -> 0 | K12: ='3HB'!C107 -> 0 | L12: =Palmitate!B107 -> 0 | M12: =Palmitate!C107 -> 0 | N12: =Oleate!B107 -> 0 | O12: =Oleate!C107 -> 0 | P12: =Linoleate!B107 -> 0.00054984413 | Q12: =Linoleate!C107 -> 0.00054984413 | R12: =Serine!B107 -> 1 | S12: =Serine!C107 -> 0 | T12: =Glycine!B107 -> 0.044840854 | U12: =Glycine!C107 -> 0.0054810883 | V12: =Citrate!B107 -> 1.3121989e-05 | W12: =Citrate!C107 -> 1.3121989e-05 | X12: =Acetate!B107 -> 0.00076685316 | Y12: =Acetate!C107 -> 0.00076685316 | Z12: =Glycerol!B107 -> 0.0076525638 | AA12: =Glycerol!C107 -> 0.0014044615 | AB12: =BCAAs!B107 -> 0 | AC12: =BCAAs!C107 -> 0 | AD12: ='6AAs'!B107 -> 0 | AE12: ='6AAs'!C107 -> 0
A13: glycine | B13: =Glucose!B108 -> 0.018190754 | C13: =Glucose!C108 -> 0.0083174891 | D13: =Lactate!B108 -> 0.023943602 | E13: =Lactate!C108 -> 0.0098429661 | F13: =Glutamine!B108 -> 0.002957974 | G13: =Glutamine!C108 -> 0.0046645158 | H13: =Alanine!B108 -> 0.00099266969 | I13: =Alanine!C108 -> 0.00099266969 | J13: ='3HB'!B108 -> 0.00051730568 | K13: ='3HB'!C108 -> 0.00051730568 | L13: =Palmitate!B108 -> 0 | M13: =Palmitate!C108 -> 0 | N13: =Oleate!B108 -> 0 | O13: =Oleate!C108 -> 0 | P13: =Linoleate!B108 -> 0.0052996791 | Q13: =Linoleate!C108 -> 0.0028053048 | R13: =Serine!B108 -> 0.17924883 | S13: =Serine!C108 -> 0.014605996 | T13: =Glycine!B108 -> 1 | U13: =Glycine!C108 -> 0 | V13: =Citrate!B108 -> 0.0025564505 | W13: =Citrate!C108 -> 0.0015592827 | X13: =Acetate!B108 -> 0.0063283362 | Y13: =Acetate!C108 -> 0.0043367069 | Z13: =Glycerol!B108 -> 0 | AA13: =Glycerol!C108 -> 0 | AB13: =BCAAs!B108 -> 0.008633892 | AC13: =BCAAs!C108 -> 0.008633892 | AD13: ='6AAs'!B108 -> 0.0093221739 | AE13: ='6AAs'!C108 -> 0.0093221739
A14: citrate | B14: =Glucose!B109 -> 0.16575221 | C14: =Glucose!C109 -> 0.0085018301 | D14: =Lactate!B109 -> 0.19602539 | E14: =Lactate!C109 -> 0.013385392 | F14: =Glutamine!B109 -> 0.06338369 | G14: =Glutamine!C109 -> 0.014741795 | H14: =Alanine!B109 -> 0.037189105 | I14: =Alanine!C109 -> 0.011584114 | J14: ='3HB'!B109 -> 0.01646145 | K14: ='3HB'!C109 -> 0.011148798 | L14: =Palmitate!B109 -> 0.013692845 | M14: =Palmitate!C109 -> 0.0010461062 | N14: =Oleate!B109 -> 0.024937336 | O14: =Oleate!C109 -> 0.01277789 | P14: =Linoleate!B109 -> 0.048788304 | Q14: =Linoleate!C109 -> 0.0081795026 | R14: =Serine!B109 -> NaN | S14: =Serine!C109 -> NaN | T14: =Glycine!B109 -> 0.0022176006 | U14: =Glycine!C109 -> 0.00047176813 | V14: =Citrate!B109 -> 1 | W14: =Citrate!C109 -> 0 | X14: =Acetate!B109 -> 0.055146538 | Y14: =Acetate!C109 -> 0.017425554 | Z14: =Glycerol!B109 -> 0.0079883087 | AA14: =Glycerol!C109 -> 0.0029628577 | AB14: =BCAAs!B109 -> 0.0096288441 | AC14: =BCAAs!C109 -> 0.0027570487 | AD14: ='6AAs'!B109 -> 0.0029168372 | AE14: ='6AAs'!C109 -> 0.0019372326
A15: acetate | B15: =Glucose!B110 -> 0.043913805 | C15: =Glucose!C110 -> 0.0020128854 | D15: =Lactate!B110 -> 0.030099051 | E15: =Lactate!C110 -> 0.0092716538 | F15: =Glutamine!B110 -> NaN | G15: =Glutamine!C110 -> NaN | H15: =Alanine!B110 -> NaN | I15: =Alanine!C110 -> NaN | J15: ='3HB'!B110 -> NaN | K15: ='3HB'!C110 -> NaN | L15: =Palmitate!B110 -> 0.0085741542 | M15: =Palmitate!C110 -> 0.00032170551 | N15: =Oleate!B110 -> 0.054866806 | O15: =Oleate!C110 -> 0.01349266 | P15: =Linoleate!B110 -> 0.14220247 | Q15: =Linoleate!C110 -> 0.036061211 | R15: =Serine!B110 -> NaN | S15: =Serine!C110 -> NaN | T15: =Glycine!B110 -> NaN | U15: =Glycine!C110 -> NaN | V15: =Citrate!B110 -> NaN | W15: =Citrate!C110 -> NaN | X15: =Acetate!B110 -> 1 | Y15: =Acetate!C110 -> 0 | Z15: =Glycerol!B110 -> 0.0045861785 | AA15: =Glycerol!C110 -> 0.0011493313 | AB15: =BCAAs!B110 -> NaN | AC15: =BCAAs!C110 -> NaN | AD15: ='6AAs'!B110 -> 0.0065874467 | AE15: ='6AAs'!C110 -> 0.001339087
... A18: 6AAs | B18: =Glucose!B113 -> 0 | C18: =Glucose!C113 -> 0 | D18: =Lactate!B113 -> 0 | E18: =Lactate!C113 -> 0 | F18: =Glutamine!B113 -> 0 | G18: =Glutamine!C113 -> 0 | H18: =Alanine!B113 -> 0 | I18: =Alanine!C113 -> 0 | J18: ='3HB'!B113 -> 0 | K18: ='3HB'!C113 -> 0 | L18: =Palmitate!B113 -> 0 | M18: =Palmitate!C113 -> 0 | N18: =Oleate!B113 -> 0 | O18: =Oleate!C113 -> 0 | P18: =Linoleate!B113 -> 0 | Q18: =Linoleate!C113 -> 0 | R18: =Serine!B113 -> 0 | S18: =Serine!C113 -> 0 | T18: =Glycine!B113 -> 0 | U18: =Glycine!C113 -> 0 | V18: =Citrate!B113 -> 0 | W18: =Citrate!C113 -> 0 | X18: =Acetate!B113 -> 0 | Y18: =Acetate!C113 -> 0 | Z18: =Glycerol!B113 -> 0 | AA18: =Glycerol!C113 -> 0 | AB18: =BCAAs!B113 -> 0 | AC18: =BCAAs!C113 -> 0 | AD18: ='6AAs'!B113 -> 1 | AE18: ='6AAs'!C113 -> 0
A20: Tissue malate
A21: Brain | B21: =Glucose!B117 -> 0.82472775 | C21: =Glucose!C117 -> 0.014912265 | D21: =Lactate!B117 -> 0.25457765 | E21: =Lactate!C117 -> 0.021990433 | F21: =Glutamine!B117 -> 0.060037028 | G21: =Glutamine!C117 -> 0.010076888 | H21: =Alanine!B117 -> 0.068898034 | I21: =Alanine!C117 -> 0.013833318 | J21: ='3HB'!B117 -> 0.0074332894 | K21: ='3HB'!C117 -> 0.00074907892 | L21: =Palmitate!B117 -> 0.0068820302 | M21: =Palmitate!C117 -> 0.0020298257 | N21: =Oleate!B117 -> 0.028706377 | O21: =Oleate!C117 -> 0.0092714053 | P21: =Linoleate!B117 -> 0.040262524 | Q21: =Linoleate!C117 -> 0.012441957 | R21: =Serine!B117 -> 0.014906985 | S21: =Serine!C117 -> 0.0009269961 | T21: =Glycine!B117 -> 0.0063207411 | U21: =Glycine!C117 -> 0.0020584711 | V21: =Citrate!B117 -> 0.0084139472 | W21: =Citrate!C117 -> 0.0017183973 | X21: =Acetate!B117 -> 0.022301908 | Y21: =Acetate!C117 -> 0.0023072405 | Z21: =Glycerol!B117 -> 0.056424379 | AA21: =Glycerol!C117 -> 0.0063841895 | AB21: =BCAAs!B117 -> 0.0091538032 | AC21: =BCAAs!C117 -> 0.0027862053 | AD21: ='6AAs'!B117 -> 0.021139697 | AE21: ='6AAs'!C117 -> 0.0014580163
A22: Muscle | B22: =Glucose!B118 -> 0.43539924 | C22: =Glucose!C118 -> 0.044458106 | D22: =Lactate!B118 -> 0.29735308 | E22: =Lactate!C118 -> 0.02552085 | F22: =Glutamine!B118 -> 0.078298153 | G22: =Glutamine!C118 -> 0.0064629733 | H22: =Alanine!B118 -> 0.074100901 | I22: =Alanine!C118 -> 0.0042893263 | J22: ='3HB'!B118 -> 0.010766319 | K22: ='3HB'!C118 -> 0.0028806447 | L22: =Palmitate!B118 -> 0.049198182 | M22: =Palmitate!C118 -> 0.0044067913 | N22: =Oleate!B118 -> 0.15304298 | O22: =Oleate!C118 -> 0.0047056363 | P22: =Linoleate!B118 -> 0.10562088 | Q22: =Linoleate!C118 -> 0.035001928 | R22: =Serine!B118 -> 0.0050457324 | S22: =Serine!C118 -> 0.00045358929 | T22: =Glycine!B118 -> 0.0039551966 | U22: =Glycine!C118 -> 0.0016588036 | V22: =Citrate!B118 -> 0.0040561191 | W22: =Citrate!C118 -> 0.0006475099 | X22: =Acetate!B118 -> 0.064713128 | Y22: =Acetate!C118 -> 0.0045467804 | Z22: =Glycerol!B118 -> 0.029544578 | AA22: =Glycerol!C118 -> 0.0074488074 | AB22: =BCAAs!B118 -> 0.046072705 | AC22: =BCAAs!C118 -> 0.0082384517 | AD22: ='6AAs'!B118 -> 0.012614462 | AE22: ='6AAs'!C118 -> 0.0035961054
A23: Kidney | B23: =Glucose!B119 -> 0.38863016 | C23: =Glucose!C119 -> 0.021579196 | D23: =Lactate!B119 -> 0.52083547 | E23: =Lactate!C119 -> 0.070715017 | F23: =Glutamine!B119 -> 0.12353107 | G23: =Glutamine!C119 -> 0.014841328 | H23: =Alanine!B119 -> 0.084779572 | I23: =Alanine!C119 -> 0.023080121 | J23: ='3HB'!B119 -> 0.048415331 | K23: ='3HB'!C119 -> 0.011193303 | L23: =Palmitate!B119 -> 0.034219172 | M23: =Palmitate!C119 -> 0.0044895123 | N23: =Oleate!B119 -> 0.093920547 | O23: =Oleate!C119 -> 0.0080658335 | P23: =Linoleate!B119 -> 0.17521999 | Q23: =Linoleate!C119 -> 0.01589186 | R23: =Serine!B119 -> 0.0064765308 | S23: =Serine!C119 -> 0.00028633783 | T23: =Glycine!B119 -> 0.0071017707 | U23: =Glycine!C119 -> 0.0018248231 | V23: =Citrate!B119 -> 0.0867263 | W23: =Citrate!C119 -> 0.012834734 | X23: =Acetate!B119 -> 0.083797703 | Y23: =Acetate!C119 -> 0.013335074 | Z23: =Glycerol!B119 -> 0.076027169 | AA23: =Glycerol!C119 -> 0.0056687725 | AB23: =BCAAs!B119 -> 0.030507101 | AC23: =BCAAs!C119 -> 0.0027324045 | AD23: ='6AAs'!B119 -> 0.022286425 | AE23: ='6AAs'!C119 -> 0.0044344274
A24: Liver | B24: =Glucose!B120 -> 0.33807861 | C24: =Glucose!C120 -> 0.031362064 | D24: =Lactate!B120 -> 0.33792811 | E24: =Lactate!C120 -> 0.02759259 | F24: =Glutamine!B120 -> 0.16110047 | G24: =Glutamine!C120 -> 0.024685665 | H24: =Alanine!B120 -> 0.11478467 | I24: =Alanine!C120 -> 0.011251076 | J24: ='3HB'!B120 -> 0.0081338013 | K24: ='3HB'!C120 -> 9.8597362e-05 | L24: =Palmitate!B120 -> 0.026041856 | M24: =Palmitate!C120 -> 0.0021263566 | N24: =Oleate!B120 -> 0.0599058 | O24: =Oleate!C120 -> 0.010281862 | P24: =Linoleate!B120 -> 0.099024725 | Q24: =Linoleate!C120 -> 0.012684907 | R24: =Serine!B120 -> 0.013889229 | S24: =Serine!C120 -> 0.0003352587 | T24: =Glycine!B120 -> 0.0082301463 | U24: =Glycine!C120 -> 0.0026549985 | V24: =Citrate!B120 -> 0.0088237934 | W24: =Citrate!C120 -> 0.0026023733 | X24: =Acetate!B120 -> 0.026058907 | Y24: =Acetate!C120 -> 0.003853477 | Z24: =Glycerol!B120 -> 0.040146729 | AA24: =Glycerol!C120 -> 0.004437702 | AB24: =BCAAs!B120 -> 0.017745791 | AC24: =BCAAs!C120 -> 0.0022532221 | AD24: ='6AAs'!B120 -> 0.049836698 | AE24: ='6AAs'!C120 -> 0.0078054608
A25: Spleen | B25: =Glucose!B121 -> 0.23031039 | C25: =Glucose!C121 -> 0.019631375 | D25: =Lactate!B121 -> 0.27777956 | E25: =Lactate!C121 -> 0.034895664 | F25: =Glutamine!B121 -> 0.2970392 | G25: =Glutamine!C121 -> 0.018874978 | H25: =Alanine!B121 -> 0.065724852 | I25: =Alanine!C121 -> 0.0087694858 | J25: ='3HB'!B121 -> 0.03425447 | K25: ='3HB'!C121 -> 0.0021300366 | L25: =Palmitate!B121 -> 0.071728546 | M25: =Palmitate!C121 -> 0.0047003601 | N25: =Oleate!B121 -> 0.12497368 | O25: =Oleate!C121 -> 0.0010913819 | P25: =Linoleate!B121 -> 0.15839834 | Q25: =Linoleate!C121 -> 0.014810021 | R25: =Serine!B121 -> 0.0060003522 | S25: =Serine!C121 -> 0.00047248811 | T25: =Glycine!B121 -> 0.0048271517 | U25: =Glycine!C121 -> 0.00038663593 | V25: =Citrate!B121 -> 0.0063955739 | W25: =Citrate!C121 -> 0.0014987046 | X25: =Acetate!B121 -> 0.15010197 | Y25: =Acetate!C121 -> 0.014139346 | Z25: =Glycerol!B121 -> 0.026053152 | AA25: =Glycerol!C121 -> 0.0056948642 | AB25: =BCAAs!B121 -> 0.027856565 | AC25: =BCAAs!C121 -> 0.0032888571 | AD25: ='6AAs'!B121 -> 0.020241455 | AE25: ='6AAs'!C121 -> 0.0026490613
A26: Skin | B26: =Glucose!B122 -> NaN | C26: =Glucose!C122 -> NaN | D26: =Lactate!B122 -> NaN | E26: =Lactate!C122 -> NaN | F26: =Glutamine!B122 -> NaN | G26: =Glutamine!C122 -> NaN | H26: =Alanine!B122 -> NaN | I26: =Alanine!C122 -> NaN | J26: ='3HB'!B122 -> NaN | K26: ='3HB'!C122 -> NaN | L26: =Palmitate!B122 -> NaN | M26: =Palmitate!C122 -> NaN | N26: =Oleate!B122 -> NaN | O26: =Oleate!C122 -> NaN | P26: =Linoleate!B122 -> 0 | Q26: =Linoleate!C122 -> 0 | R26: =Serine!B122 -> NaN | S26: =Serine!C122 -> NaN | T26: =Glycine!B122 -> 0 | U26: =Glycine!C122 -> 0 | V26: =Citrate!B122 -> NaN | W26: =Citrate!C122 -> NaN | X26: =Acetate!B122 -> NaN | Y26: =Acetate!C122 -> NaN | Z26: =Glycerol!B122 -> NaN | AA26: =Glycerol!C122 -> NaN | AB26: =BCAAs!B122 -> NaN | AC26: =BCAAs!C122 -> NaN | AD26: ='6AAs'!B122 -> NaN | AE26: ='6AAs'!C122 -> NaN
A27: Pancreas | B27: =Glucose!B123 -> 0.27616406 | C27: =Glucose!C123 -> 0.012713912 | D27: =Lactate!B123 -> 0.33830353 | E27: =Lactate!C123 -> 0.024741191 | F27: =Glutamine!B123 -> 0.37818852 | G27: =Glutamine!C123 -> 0.039984436 | H27: =Alanine!B123 -> 0.19179787 | I27: =Alanine!C123 -> 0.0266618 | J27: ='3HB'!B123 -> 0.019710377 | K27: ='3HB'!C123 -> 0.0024308373 | L27: =Palmitate!B123 -> 0.023024971 | M27: =Palmitate!C123 -> 0.0022686884 | N27: =Oleate!B123 -> 0.073936618 | O27: =Oleate!C123 -> 0.0048283767 | P27: =Linoleate!B123 -> 0.098129216 | Q27: =Linoleate!C123 -> 0.014241957 | R27: =Serine!B123 -> 0.014762357 | S27: =Serine!C123 -> 0.001100438 | T27: =Glycine!B123 -> 0.0083810242 | U27: =Glycine!C123 -> 0.00059461257 | V27: =Citrate!B123 -> 0.0075652496 | W27: =Citrate!C123 -> 0.0029075783 | X27: =Acetate!B123 -> 0.04826968 | Y27: =Acetate!C123 -> 0.010235927 | Z27: =Glycerol!B123 -> 0.028541797 | AA27: =Glycerol!C123 -> 0.0035591559 | AB27: =BCAAs!B123 -> 0.16916592 | AC27: =BCAAs!C123 -> 0.028379646 | AD27: ='6AAs'!B123 -> 0.040562553 | AE27: ='6AAs'!C123 -> 0.0058245759
A28: Lung | B28: =Glucose!B124 -> 0.37599128 | C28: =Glucose!C124 -> 0.013376853 | D28: =Lactate!B124 -> 0.38974615 | E28: =Lactate!C124 -> 0.041881449 | F28: =Glutamine!B124 -> 0.11724703 | G28: =Glutamine!C124 -> 0.0089944467 | H28: =Alanine!B124 -> 0.08898453 | I28: =Alanine!C124 -> 0.021047195 | J28: ='3HB'!B124 -> 0.016717369 | K28: ='3HB'!C124 -> #DIV/0! | L28: =Palmitate!B124 -> 0.072842048 | M28: =Palmitate!C124 -> 0.0051557591 | N28: =Oleate!B124 -> 0.11882323 | O28: =Oleate!C124 -> 0.00084875439 | P28: =Linoleate!B124 -> 0.12458943 | Q28: =Linoleate!C124 -> 0.021472628 | R28: =Serine!B124 -> 0.0066241382 | S28: =Serine!C124 -> 0.00018284557 | T28: =Glycine!B124 -> 0.005460357 | U28: =Glycine!C124 -> 0.0012540078 | V28: =Citrate!B124 -> 0.010473726 | W28: =Citrate!C124 -> 0.0016053813 | X28: =Acetate!B124 -> 0.10860811 | Y28: =Acetate!C124 -> 0.015206613 | Z28: =Glycerol!B124 -> 0.043475652 | AA28: =Glycerol!C124 -> 0.0045735165 | AB28: =BCAAs!B124 -> 0.037019661 | AC28: =BCAAs!C124 -> 0.0046826709 | AD28: ='6AAs'!B124 -> 0.01648071 | AE28: ='6AAs'!C124 -> 0.0020688515
A29: Heart | B29: =Glucose!B125 -> 0.5049399 | C29: =Glucose!C125 -> 0.058579573 | D29: =Lactate!B125 -> 0.31846465 | E29: =Lactate!C125 -> 0.0337767 | F29: =Glutamine!B125 -> 0.041858935 | G29: =Glutamine!C125 -> 0.0043620294 | H29: =Alanine!B125 -> 0.058199665 | I29: =Alanine!C125 -> 0.0024351531 | J29: ='3HB'!B125 -> 0.019511983 | K29: ='3HB'!C125 -> 0.001524531 | L29: =Palmitate!B125 -> 0.081058165 | M29: =Palmitate!C125 -> 0.0045155459 | N29: =Oleate!B125 -> 0.15099692 | O29: =Oleate!C125 -> 0.014287635 | P29: =Linoleate!B125 -> 0.15961851 | Q29: =Linoleate!C125 -> 0.019013604 | R29: =Serine!B125 -> 0.0044373018 | S29: =Serine!C125 -> 0.00062941065 | T29: =Glycine!B125 -> 0.006686683 | U29: =Glycine!C125 -> 0.0011989364 | V29: =Citrate!B125 -> 0.0064755518 | W29: =Citrate!C125 -> 0.0010926999 | X29: =Acetate!B125 -> 0.067659469 | Y29: =Acetate!C125 -> 0.0034807476 | Z29: =Glycerol!B125 -> 0.045727118 | AA29: =Glycerol!C125 -> 0.0060290985 | AB29: =BCAAs!B125 -> 0.011481526 | AC29: =BCAAs!C125 -> 0.0029435022 | AD29: ='6AAs'!B125 -> 0.010541688 | AE29: ='6AAs'!C125 -> 0.0029056934
